Workbook

Sheet R-T Table
A1: MF52E-503H3950FAL36 NTC Thermistor R-T Table
A2: Part No. | B2: MF52E-503H3950FAL36
A3: R25 (25°C) | B3: 50 kΩ ±3%
A4: B25/50 | B4: 3950 K ±1%
A5: Operating Range | B5: -40°C ~ +125°C
A6: Source | B6: Ampron MO190160 (2019-08-14)
A8: T (°C) | B8: Rmin (kΩ) | C8: Rnom (kΩ) | D8: Rmax (kΩ) | E8: Tolerance (±%)
A9: -40 | B9: 1569.605 | C9: 1675.991 | D9: 1787.977 | E9: =ROUND((D9-B9)/C9/2*100,2) -> 6.51
A10: -39 | B10: 1467.665 | C10: 1566.079 | D10: 1669.588 | E10: =ROUND((D10-B10)/C10/2*100,2) -> 6.45
A11: -38 | B11: 1373.68 | C11: 1464.812 | D11: 1560.584 | E11: =ROUND((D11-B11)/C11/2*100,2) -> 6.38
A12: -37 | B12: 1286.868 | C12: 1371.336 | D12: 1460.033 | E12: =ROUND((D12-B12)/C12/2*100,2) -> 6.31
A13: -36 | B13: 1206.54 | C13: 1284.899 | D13: 1367.116 | E13: =ROUND((D13-B13)/C13/2*100,2) -> 6.25
A14: -35 | B14: 1132.095 | C14: 1204.844 | D14: 1281.113 | E14: =ROUND((D14-B14)/C14/2*100,2) -> 6.18
A15: -34 | B15: 1062.994 | C15: 1130.582 | D15: 1201.387 | E15: =ROUND((D15-B15)/C15/2*100,2) -> 6.12
A16: -33 | B16: 998.763 | C16: 1061.599 | D16: 1127.373 | E16: =ROUND((D16-B16)/C16/2*100,2) -> 6.06
A17: -32 | B17: 938.982 | C17: 997.435 | D17: 1058.574 | E17: =ROUND((D17-B17)/C17/2*100,2) -> 5.99
A18: -31 | B18: 883.273 | C18: 937.679 | D18: 994.54 | E18: =ROUND((D18-B18)/C18/2*100,2) -> 5.93
A19: -30 | B19: 831.302 | C19: 881.966 | D19: 934.876 | E19: =ROUND((D19-B19)/C19/2*100,2) -> 5.87
A20: -29 | B20: 782.766 | C20: 829.968 | D20: 879.224 | E20: =ROUND((D20-B20)/C20/2*100,2) -> 5.81
... A199: 150 | B199: 0.813 | C199: 0.873 | D199: 0.936 | E199: =ROUND((D199-B199)/C199/2*100,2) -> 7.04

Sheet ADC Pull-up
A1: Pull-up 방식 — VDD─[Rpull]─(ADC)─[NTC]─GND (T↑ → V_ADC↓)
A2: VDD (V) | B2: 2.3
A3: Pull 저항 (kΩ) | B3: 15
A4: ADC 해상도 (bit) | B4: 10
A5: 회로 구성 | B5: VDD ─[Rpull]─ (ADC) ─[NTC]─ GND | V_ADC = VDD × Rntc / (Rpull + Rntc)
A7: T (°C) | B7: Rnom (kΩ) | C7: V_ADC (V) | D7: V/VDD | E7: ADC count | F7: 비고
A8: ='R-T Table'!A9 -> -40 | B8: ='R-T Table'!C9 -> 1675.991 | C8: =$B$2*B8/($B$3+B8) -> 2.2795978 | D8: =C8/$B$2 -> 0.99112946 | E8: =ROUND(D8*(2^$B$4-1),0) -> 1014 | F8: 동작 범위 끝
A9: ='R-T Table'!A10 -> -39 | B9: ='R-T Table'!C10 -> 1566.079 | C9: =$B$2*B9/($B$3+B9) -> 2.2781795 | D9: =C9/$B$2 -> 0.99051281 | E9: =ROUND(D9*(2^$B$4-1),0) -> 1013
A10: ='R-T Table'!A11 -> -38 | B10: ='R-T Table'!C11 -> 1464.812 | C10: =$B$2*B10/($B$3+B10) -> 2.2766862 | D10: =C10/$B$2 -> 0.98986358 | E10: =ROUND(D10*(2^$B$4-1),0) -> 1013
A11: ='R-T Table'!A12 -> -37 | B11: ='R-T Table'!C12 -> 1371.336 | C11: =$B$2*B11/($B$3+B11) -> 2.2751143 | D11: =C11/$B$2 -> 0.98918011 | E11: =ROUND(D11*(2^$B$4-1),0) -> 1012
A12: ='R-T Table'!A13 -> -36 | B12: ='R-T Table'!C13 -> 1284.899 | C12: =$B$2*B12/($B$3+B12) -> 2.2734595 | D12: =C12/$B$2 -> 0.98846064 | E12: =ROUND(D12*(2^$B$4-1),0) -> 1011
A13: ='R-T Table'!A14 -> -35 | B13: ='R-T Table'!C14 -> 1204.844 | C13: =$B$2*B13/($B$3+B13) -> 2.2717177 | D13: =C13/$B$2 -> 0.98770335 | E13: =ROUND(D13*(2^$B$4-1),0) -> 1010
A14: ='R-T Table'!A15 -> -34 | B14: ='R-T Table'!C15 -> 1130.582 | C14: =$B$2*B14/($B$3+B14) -> 2.2698843 | D14: =C14/$B$2 -> 0.98690622 | E14: =ROUND(D14*(2^$B$4-1),0) -> 1010
A15: ='R-T Table'!A16 -> -33 | B15: ='R-T Table'!C16 -> 1061.599 | C15: =$B$2*B15/($B$3+B15) -> 2.2679546 | D15: =C15/$B$2 -> 0.98606724 | E15: =ROUND(D15*(2^$B$4-1),0) -> 1009
A16: ='R-T Table'!A17 -> -32 | B16: ='R-T Table'!C17 -> 997.435 | C16: =$B$2*B16/($B$3+B16) -> 2.2659237 | D16: =C16/$B$2 -> 0.98518423 | E16: =ROUND(D16*(2^$B$4-1),0) -> 1008
A17: ='R-T Table'!A18 -> -31 | B17: ='R-T Table'!C18 -> 937.679 | C17: =$B$2*B17/($B$3+B17) -> 2.2637863 | D17: =C17/$B$2 -> 0.98425493 | E17: =ROUND(D17*(2^$B$4-1),0) -> 1007
A18: ='R-T Table'!A19 -> -30 | B18: ='R-T Table'!C19 -> 881.966 | C18: =$B$2*B18/($B$3+B18) -> 2.261537 | D18: =C18/$B$2 -> 0.98327696 | E18: =ROUND(D18*(2^$B$4-1),0) -> 1006
A19: ='R-T Table'!A20 -> -29 | B19: ='R-T Table'!C20 -> 829.968 | C19: =$B$2*B19/($B$3+B19) -> 2.2591701 | D19: =C19/$B$2 -> 0.98224785 | E19: =ROUND(D19*(2^$B$4-1),0) -> 1005
A20: ='R-T Table'!A21 -> -28 | B20: ='R-T Table'!C21 -> 781.389 | C20: =$B$2*B20/($B$3+B20) -> 2.2566795 | D20: =C20/$B$2 -> 0.98116498 | E20: =ROUND(D20*(2^$B$4-1),0) -> 1004
... A72: ='R-T Table'!A73 -> 24 | B72: ='R-T Table'!C73 -> 52.129 | C72: =$B$2*B72/($B$3+B72) -> 1.7860641 | D72: =C72/$B$2 -> 0.77654963 | E72: =ROUND(D72*(2^$B$4-1),0) -> 794
A73: ='R-T Table'!A74 -> 25 | B73: ='R-T Table'!C74 -> 50 | C73: =$B$2*B73/($B$3+B73) -> 1.7692308 | D73: =C73/$B$2 -> 0.76923077 | E73: =ROUND(D73*(2^$B$4-1),0) -> 787 | F73: ← R25 기준
A74: ='R-T Table'!A75 -> 26 | B74: ='R-T Table'!C75 -> 47.862 | C74: =$B$2*B74/($B$3+B74) -> 1.7511788 | D74: =C74/$B$2 -> 0.76138208 | E74: =ROUND(D74*(2^$B$4-1),0) -> 779
A75: ='R-T Table'!A76 -> 27 | B75: ='R-T Table'!C76 -> 45.826 | C75: =$B$2*B75/($B$3+B75) -> 1.7328083 | D75: =C75/$B$2 -> 0.75339493 | E75: =ROUND(D75*(2^$B$4-1),0) -> 771
A76: ='R-T Table'!A77 -> 28 | B76: ='R-T Table'!C77 -> 43.886 | C76: =$B$2*B76/($B$3+B76) -> 1.7141222 | D76: =C76/$B$2 -> 0.74527052 | E76: =ROUND(D76*(2^$B$4-1),0) -> 762
A77: ='R-T Table'!A78 -> 29 | B77: ='R-T Table'!C78 -> 42.039 | C77: =$B$2*B77/($B$3+B77) -> 1.6951507 | D77: =C77/$B$2 -> 0.73702204 | E77: =ROUND(D77*(2^$B$4-1),0) -> 754
A78: ='R-T Table'!A79 -> 30 | B78: ='R-T Table'!C79 -> 40.279 | C78: =$B$2*B78/($B$3+B78) -> 1.6758932 | D78: =C78/$B$2 -> 0.72864922 | E78: =ROUND(D78*(2^$B$4-1),0) -> 745
A79: ='R-T Table'!A80 -> 31 | B79: ='R-T Table'!C80 -> 38.601 | C79: =$B$2*B79/($B$3+B79) -> 1.6563553 | D79: =C79/$B$2 -> 0.72015447 | E79: =ROUND(D79*(2^$B$4-1),0) -> 737
A80: ='R-T Table'!A81 -> 32 | B80: ='R-T Table'!C81 -> 37.002 | C80: =$B$2*B80/($B$3+B80) -> 1.636564 | D80: =C80/$B$2 -> 0.71154956 | E80: =ROUND(D80*(2^$B$4-1),0) -> 728
A81: ='R-T Table'!A82 -> 33 | B81: ='R-T Table'!C82 -> 35.477 | C81: =$B$2*B81/($B$3+B81) -> 1.6165204 | D81: =C81/$B$2 -> 0.70283495 | E81: =ROUND(D81*(2^$B$4-1),0) -> 719
A82: ='R-T Table'!A83 -> 34 | B82: ='R-T Table'!C83 -> 34.022 | C82: =$B$2*B82/($B$3+B82) -> 1.5962343 | D82: =C82/$B$2 -> 0.69401493 | E82: =ROUND(D82*(2^$B$4-1),0) -> 710
A83: ='R-T Table'!A84 -> 35 | B83: ='R-T Table'!C84 -> 32.635 | C83: =$B$2*B83/($B$3+B83) -> 1.5757426 | D83: =C83/$B$2 -> 0.68510549 | E83: =ROUND(D83*(2^$B$4-1),0) -> 701
A84: ='R-T Table'!A85 -> 36 | B84: ='R-T Table'!C85 -> 31.311 | C84: =$B$2*B84/($B$3+B84) -> 1.5550366 | D84: =C84/$B$2 -> 0.67610287 | E84: =ROUND(D84*(2^$B$4-1),0) -> 692
A85: ='R-T Table'!A86 -> 37 | B85: ='R-T Table'!C86 -> 30.048 | C85: =$B$2*B85/($B$3+B85) -> 1.5341502 | D85: =C85/$B$2 -> 0.66702184 | E85: =ROUND(D85*(2^$B$4-1),0) -> 682
... A172: ='R-T Table'!A173 -> 124 | B172: ='R-T Table'!C173 -> 1.685 | C172: =$B$2*B172/($B$3+B172) -> 0.2322745 | D172: =C172/$B$2 -> 0.10098891 | E172: =ROUND(D172*(2^$B$4-1),0) -> 103
A173: ='R-T Table'!A174 -> 125 | B173: ='R-T Table'!C174 -> 1.641 | C173: =$B$2*B173/($B$3+B173) -> 0.22680728 | D173: =C173/$B$2 -> 0.098611862 | E173: =ROUND(D173*(2^$B$4-1),0) -> 101 | F173: 동작 범위 끝
A174: ='R-T Table'!A175 -> 126 | B174: ='R-T Table'!C175 -> 1.598 | C174: =$B$2*B174/($B$3+B174) -> 0.22143632 | D174: =C174/$B$2 -> 0.09627666 | E174: =ROUND(D174*(2^$B$4-1),0) -> 98
A175: ='R-T Table'!A176 -> 127 | B175: ='R-T Table'!C176 -> 1.556 | C175: =$B$2*B175/($B$3+B175) -> 0.21616332 | D175: =C175/$B$2 -> 0.093984054 | E175: =ROUND(D175*(2^$B$4-1),0) -> 96
A176: ='R-T Table'!A177 -> 128 | B176: ='R-T Table'!C177 -> 1.516 | C176: =$B$2*B176/($B$3+B176) -> 0.21111649 | D176: =C176/$B$2 -> 0.09178978 | E176: =ROUND(D176*(2^$B$4-1),0) -> 94
A177: ='R-T Table'!A178 -> 129 | B177: ='R-T Table'!C178 -> 1.477 | C177: =$B$2*B177/($B$3+B177) -> 0.20617224 | D177: =C177/$B$2 -> 0.089640104 | E177: =ROUND(D177*(2^$B$4-1),0) -> 92
A178: ='R-T Table'!A179 -> 130 | B178: ='R-T Table'!C179 -> 1.439 | C178: =$B$2*B178/($B$3+B178) -> 0.2013322 | D178: =C178/$B$2 -> 0.087535738 | E178: =ROUND(D178*(2^$B$4-1),0) -> 90
...

Sheet ADC Pull-down
A1: Pull-down 방식 — VDD─[NTC]─(ADC)─[Rpull]─GND (T↑ → V_ADC↑)
A2: VDD (V) | B2: 2.3
A3: Pull 저항 (kΩ) | B3: 15
A4: ADC 해상도 (bit) | B4: 10
A5: 회로 구성 | B5: VDD ─[NTC]─ (ADC) ─[Rpull]─ GND | V_ADC = VDD × Rpull / (Rntc + Rpull)
A7: T (°C) | B7: Rnom (kΩ) | C7: V_ADC (V) | D7: V/VDD | E7: ADC count | F7: 비고
A8: ='R-T Table'!A9 -> -40 | B8: ='R-T Table'!C9 -> 1675.991 | C8: =$B$2*$B$3/(B8+$B$3) -> 0.020402238 | D8: =C8/$B$2 -> 0.008870538 | E8: =ROUND(D8*(2^$B$4-1),0) -> 9 | F8: 동작 범위 끝
A9: ='R-T Table'!A10 -> -39 | B9: ='R-T Table'!C10 -> 1566.079 | C9: =$B$2*$B$3/(B9+$B$3) -> 0.021820542 | D9: =C9/$B$2 -> 0.009487192 | E9: =ROUND(D9*(2^$B$4-1),0) -> 10
A10: ='R-T Table'!A11 -> -38 | B10: ='R-T Table'!C11 -> 1464.812 | C10: =$B$2*$B$3/(B10+$B$3) -> 0.023313772 | D10: =C10/$B$2 -> 0.010136423 | E10: =ROUND(D10*(2^$B$4-1),0) -> 10
A11: ='R-T Table'!A12 -> -37 | B11: ='R-T Table'!C12 -> 1371.336 | C11: =$B$2*$B$3/(B11+$B$3) -> 0.024885742 | D11: =C11/$B$2 -> 0.010819888 | E11: =ROUND(D11*(2^$B$4-1),0) -> 11
A12: ='R-T Table'!A13 -> -36 | B12: ='R-T Table'!C13 -> 1284.899 | C12: =$B$2*$B$3/(B12+$B$3) -> 0.026540524 | D12: =C12/$B$2 -> 0.011539358 | E12: =ROUND(D12*(2^$B$4-1),0) -> 12
A13: ='R-T Table'!A14 -> -35 | B13: ='R-T Table'!C14 -> 1204.844 | C13: =$B$2*$B$3/(B13+$B$3) -> 0.028282305 | D13: =C13/$B$2 -> 0.012296654 | E13: =ROUND(D13*(2^$B$4-1),0) -> 13
A14: ='R-T Table'!A15 -> -34 | B14: ='R-T Table'!C15 -> 1130.582 | C14: =$B$2*$B$3/(B14+$B$3) -> 0.030115697 | D14: =C14/$B$2 -> 0.013093781 | E14: =ROUND(D14*(2^$B$4-1),0) -> 13
A15: ='R-T Table'!A16 -> -33 | B15: ='R-T Table'!C16 -> 1061.599 | C15: =$B$2*$B$3/(B15+$B$3) -> 0.032045358 | D15: =C15/$B$2 -> 0.013932764 | E15: =ROUND(D15*(2^$B$4-1),0) -> 14
A16: ='R-T Table'!A17 -> -32 | B16: ='R-T Table'!C17 -> 997.435 | C16: =$B$2*$B$3/(B16+$B$3) -> 0.034076262 | D16: =C16/$B$2 -> 0.014815766 | E16: =ROUND(D16*(2^$B$4-1),0) -> 15
A17: ='R-T Table'!A18 -> -31 | B17: ='R-T Table'!C18 -> 937.679 | C17: =$B$2*$B$3/(B17+$B$3) -> 0.036213667 | D17: =C17/$B$2 -> 0.015745073 | E17: =ROUND(D17*(2^$B$4-1),0) -> 16
A18: ='R-T Table'!A19 -> -30 | B18: ='R-T Table'!C19 -> 881.966 | C18: =$B$2*$B$3/(B18+$B$3) -> 0.038462996 | D18: =C18/$B$2 -> 0.016723042 | E18: =ROUND(D18*(2^$B$4-1),0) -> 17
A19: ='R-T Table'!A20 -> -29 | B19: ='R-T Table'!C20 -> 829.968 | C19: =$B$2*$B$3/(B19+$B$3) -> 0.040829949 | D19: =C19/$B$2 -> 0.017752152 | E19: =ROUND(D19*(2^$B$4-1),0) -> 18
A20: ='R-T Table'!A21 -> -28 | B20: ='R-T Table'!C21 -> 781.389 | C20: =$B$2*$B$3/(B20+$B$3) -> 0.043320538 | D20: =C20/$B$2 -> 0.018835017 | E20: =ROUND(D20*(2^$B$4-1),0) -> 19
... A47: ='R-T Table'!A48 -> -1 | B47: ='R-T Table'!C48 -> 171.887 | C47: =$B$2*$B$3/(B47+$B$3) -> 0.18460353 | D47: =C47/$B$2 -> 0.080262405 | E47: =ROUND(D47*(2^$B$4-1),0) -> 82
A48: ='R-T Table'!A49 -> 0 | B48: ='R-T Table'!C49 -> 163.126 | C48: =$B$2*$B$3/(B48+$B$3) -> 0.19368312 | D48: =C48/$B$2 -> 0.084210054 | E48: =ROUND(D48*(2^$B$4-1),0) -> 86 | U48: Temp_Table | V48: [ | W48: 0 | X48: ] | Y48: = | Z48: =E48 -> 86 | AA48: ; | AB48: =Z48-Z47 -> 86 | AD48: 0 | AE48: =A28 -> -20 | AF48: =E28 -> 30 | AG48: ,
A49: ='R-T Table'!A50 -> 1 | B49: ='R-T Table'!C50 -> 154.859 | C49: =$B$2*$B$3/(B49+$B$3) -> 0.20310964 | D49: =C49/$B$2 -> 0.088308538 | E49: =ROUND(D49*(2^$B$4-1),0) -> 90 | U49: Temp_Table | V49: [ | W49: 1 | X49: ] | Y49: = | Z49: =E49 -> 90 | AA49: ; | AB49: =Z49-Z48 -> 4 | AD49: 1 | AE49: =A29 -> -19 | AF49: =E29 -> 32 | AG49: ,
A50: ='R-T Table'!A51 -> 2 | B50: ='R-T Table'!C51 -> 147.058 | C50: =$B$2*$B$3/(B50+$B$3) -> 0.21288674 | D50: =C50/$B$2 -> 0.092559454 | E50: =ROUND(D50*(2^$B$4-1),0) -> 95 | U50: Temp_Table | V50: [ | W50: 2 | X50: ] | Y50: = | Z50: =E50 -> 95 | AA50: ; | AB50: =Z50-Z49 -> 5 | AD50: 2 | AE50: =A30 -> -18 | AF50: =E30 -> 34 | AG50: ,
A51: ='R-T Table'!A52 -> 3 | B51: ='R-T Table'!C52 -> 139.696 | C51: =$B$2*$B$3/(B51+$B$3) -> 0.22301805 | D51: =C51/$B$2 -> 0.096964369 | E51: =ROUND(D51*(2^$B$4-1),0) -> 99 | U51: Temp_Table | V51: [ | W51: 3 | X51: ] | Y51: = | Z51: =E51 -> 99 | AA51: ; | AB51: =Z51-Z50 -> 4 | AD51: 3 | AE51: =A31 -> -17 | AF51: =E31 -> 36 | AG51: ,
A52: ='R-T Table'!A53 -> 4 | B52: ='R-T Table'!C53 -> 132.747 | C52: =$B$2*$B$3/(B52+$B$3) -> 0.23350728 | D52: =C52/$B$2 -> 0.1015249 | E52: =ROUND(D52*(2^$B$4-1),0) -> 104 | U52: Temp_Table | V52: [ | W52: 4 | X52: ] | Y52: = | Z52: =E52 -> 104 | AA52: ; | AB52: =Z52-Z51 -> 5 | AD52: 4 | AE52: =A32 -> -16 | AF52: =E32 -> 38 | AG52: ,
A53: ='R-T Table'!A54 -> 5 | B53: ='R-T Table'!C54 -> 126.187 | C53: =$B$2*$B$3/(B53+$B$3) -> 0.24435678 | D53: =C53/$B$2 -> 0.10624208 | E53: =ROUND(D53*(2^$B$4-1),0) -> 109 | U53: Temp_Table | V53: [ | W53: 5 | X53: ] | Y53: = | Z53: =E53 -> 109 | AA53: ; | AB53: =Z53-Z52 -> 5 | AD53: 5 | AE53: =A33 -> -15 | AF53: =E33 -> 40 | AG53: ,
A54: ='R-T Table'!A55 -> 6 | B54: ='R-T Table'!C55 -> 119.994 | C54: =$B$2*$B$3/(B54+$B$3) -> 0.25556691 | D54: =C54/$B$2 -> 0.11111605 | E54: =ROUND(D54*(2^$B$4-1),0) -> 114 | U54: Temp_Table | V54: [ | W54: 6 | X54: ] | Y54: = | Z54: =E54 -> 114 | AA54: ; | AB54: =Z54-Z53 -> 5 | AD54: 6 | AE54: =A34 -> -14 | AF54: =E34 -> 42 | AG54: ,
A55: ='R-T Table'!A56 -> 7 | B55: ='R-T Table'!C56 -> 114.147 | C55: =$B$2*$B$3/(B55+$B$3) -> 0.26713745 | D55: =C55/$B$2 -> 0.11614672 | E55: =ROUND(D55*(2^$B$4-1),0) -> 119 | U55: Temp_Table | V55: [ | W55: 7 | X55: ] | Y55: = | Z55: =E55 -> 119 | AA55: ; | AB55: =Z55-Z54 -> 5 | AD55: 7 | AE55: =A35 -> -13 | AF55: =E35 -> 45 | AG55: ,
A56: ='R-T Table'!A57 -> 8 | B56: ='R-T Table'!C57 -> 108.626 | C56: =$B$2*$B$3/(B56+$B$3) -> 0.27906751 | D56: =C56/$B$2 -> 0.1213337 | E56: =ROUND(D56*(2^$B$4-1),0) -> 124 | U56: Temp_Table | V56: [ | W56: 8 | X56: ] | Y56: = | Z56: =E56 -> 124 | AA56: ; | AB56: =Z56-Z55 -> 5 | AD56: 8 | AE56: =A36 -> -12 | AF56: =E36 -> 47 | AG56: ,
A57: ='R-T Table'!A58 -> 9 | B57: ='R-T Table'!C58 -> 103.411 | C57: =$B$2*$B$3/(B57+$B$3) -> 0.29135807 | D57: =C57/$B$2 -> 0.12667742 | E57: =ROUND(D57*(2^$B$4-1),0) -> 130 | U57: Temp_Table | V57: [ | W57: 9 | X57: ] | Y57: = | Z57: =E57 -> 130 | AA57: ; | AB57: =Z57-Z56 -> 6 | AD57: 9 | AE57: =A37 -> -11 | AF57: =E37 -> 50 | AG57: ,
A58: ='R-T Table'!A59 -> 10 | B58: ='R-T Table'!C59 -> 98.486 | C58: =$B$2*$B$3/(B58+$B$3) -> 0.30400226 | D58: =C58/$B$2 -> 0.13217489 | E58: =ROUND(D58*(2^$B$4-1),0) -> 135 | U58: Temp_Table | V58: [ | W58: 10 | X58: ] | Y58: = | Z58: =E58 -> 135 | AA58: ; | AB58: =Z58-Z57 -> 5 | AD58: 10 | AE58: =A38 -> -10 | AF58: =E38 -> 52 | AG58: ,
A59: ='R-T Table'!A60 -> 11 | B59: ='R-T Table'!C60 -> 93.833 | C59: =$B$2*$B$3/(B59+$B$3) -> 0.31699944 | D59: =C59/$B$2 -> 0.13782584 | E59: =ROUND(D59*(2^$B$4-1),0) -> 141 | U59: Temp_Table | V59: [ | W59: 11 | X59: ] | Y59: = | Z59: =E59 -> 141 | AA59: ; | AB59: =Z59-Z58 -> 6 | AD59: 11 | AE59: =A39 -> -9 | AF59: =E39 -> 55 | AG59: ,
... A72: ='R-T Table'!A73 -> 24 | B72: ='R-T Table'!C73 -> 52.129 | C72: =$B$2*$B$3/(B72+$B$3) -> 0.51393585 | D72: =C72/$B$2 -> 0.22345037 | E72: =ROUND(D72*(2^$B$4-1),0) -> 229 | U72: Temp_Table | V72: [ | W72: 24 | X72: ] | Y72: = | Z72: =E72 -> 229 | AA72: ; | AB72: =Z72-Z71 -> 8 | AD72: 24 | AE72: =A52 -> 4 | AF72: =E52 -> 104 | AG72: ,
A73: ='R-T Table'!A74 -> 25 | B73: ='R-T Table'!C74 -> 50 | C73: =$B$2*$B$3/(B73+$B$3) -> 0.53076923 | D73: =C73/$B$2 -> 0.23076923 | E73: =ROUND(D73*(2^$B$4-1),0) -> 236 | F73: ← R25 기준 | U73: Temp_Table | V73: [ | W73: 25 | X73: ] | Y73: = | Z73: =E73 -> 236 | AA73: ; | AB73: =Z73-Z72 -> 7 | AD73: 25 | AE73: =A53 -> 5 | AF73: =E53 -> 109 | AG73: ,
A74: ='R-T Table'!A75 -> 26 | B74: ='R-T Table'!C75 -> 47.862 | C74: =$B$2*$B$3/(B74+$B$3) -> 0.54882123 | D74: =C74/$B$2 -> 0.23861792 | E74: =ROUND(D74*(2^$B$4-1),0) -> 244 | U74: Temp_Table | V74: [ | W74: 26 | X74: ] | Y74: = | Z74: =E74 -> 244 | AA74: ; | AB74: =Z74-Z73 -> 8 | AD74: 26 | AE74: =A54 -> 6 | AF74: =E54 -> 114 | AG74: ,
A75: ='R-T Table'!A76 -> 27 | B75: ='R-T Table'!C76 -> 45.826 | C75: =$B$2*$B$3/(B75+$B$3) -> 0.56719166 | D75: =C75/$B$2 -> 0.24660507 | E75: =ROUND(D75*(2^$B$4-1),0) -> 252 | U75: Temp_Table | V75: [ | W75: 27 | X75: ] | Y75: = | Z75: =E75 -> 252 | AA75: ; | AB75: =Z75-Z74 -> 8 | AD75: 27 | AE75: =A55 -> 7 | AF75: =E55 -> 119 | AG75: ,
A76: ='R-T Table'!A77 -> 28 | B76: ='R-T Table'!C77 -> 43.886 | C76: =$B$2*$B$3/(B76+$B$3) -> 0.5858778 | D76: =C76/$B$2 -> 0.25472948 | E76: =ROUND(D76*(2^$B$4-1),0) -> 261 | U76: Temp_Table | V76: [ | W76: 28 | X76: ] | Y76: = | Z76: =E76 -> 261 | AA76: ; | AB76: =Z76-Z75 -> 9 | AD76: 28 | AE76: =A56 -> 8 | AF76: =E56 -> 124 | AG76: ,
A77: ='R-T Table'!A78 -> 29 | B77: ='R-T Table'!C78 -> 42.039 | C77: =$B$2*$B$3/(B77+$B$3) -> 0.60484931 | D77: =C77/$B$2 -> 0.26297796 | E77: =ROUND(D77*(2^$B$4-1),0) -> 269 | U77: Temp_Table | V77: [ | W77: 29 | X77: ] | Y77: = | Z77: =E77 -> 269 | AA77: ; | AB77: =Z77-Z76 -> 8 | AD77: 29 | AE77: =A57 -> 9 | AF77: =E57 -> 130 | AG77: ,
A78: ='R-T Table'!A79 -> 30 | B78: ='R-T Table'!C79 -> 40.279 | C78: =$B$2*$B$3/(B78+$B$3) -> 0.6241068 | D78: =C78/$B$2 -> 0.27135078 | E78: =ROUND(D78*(2^$B$4-1),0) -> 278 | U78: Temp_Table | V78: [ | W78: 30 | X78: ] | Y78: = | Z78: =E78 -> 278 | AA78: ; | AB78: =Z78-Z77 -> 9 | AD78: 30 | AE78: =A58 -> 10 | AF78: =E58 -> 135 | AG78: ,
A79: ='R-T Table'!A80 -> 31 | B79: ='R-T Table'!C80 -> 38.601 | C79: =$B$2*$B$3/(B79+$B$3) -> 0.64364471 | D79: =C79/$B$2 -> 0.27984553 | E79: =ROUND(D79*(2^$B$4-1),0) -> 286 | U79: Temp_Table | V79: [ | W79: 31 | X79: ] | Y79: = | Z79: =E79 -> 286 | AA79: ; | AB79: =Z79-Z78 -> 8 | AD79: 31 | AE79: =A59 -> 11 | AF79: =E59 -> 141 | AG79: ,
...
